<sdf version='1.7'>
  <world name='default'>
    <gravity>0 0 -9.8</gravity>
    <physics name='default_physics' default='0' type='ode'>
      <max_step_size>0.001</max_step_size>
      <real_time_factor>1</real_time_factor>
      <real_time_update_rate>1000</real_time_update_rate>
    </physics>
    <model name='aws_robomaker_warehouse_RoofB_01_001'>
      <frame name='aws_robomaker_warehouse_RoofB_01::__model__' attached_to='aws_robomaker_warehouse_RoofB_01::link'>
        <pose relative_to='__model__'>0 0 0 0 -0 0</pose>
      </frame>
      <link name='aws_robomaker_warehouse_RoofB_01::link'>
        <inertial>
          <mass>1000</mass>
          <pose>0 0 0 0 -0 0</pose>
          <inertia>
            <ixx>834025</ixx>
            <ixy>0</ixy>
            <ixz>0</ixz>
            <iyy>459441</iyy>
            <iyz>0</iyz>
            <izz>1.30208e+06</izz>
          </inertia>
        </inertial>
        <collision name='collision'>
          <geometry>
            <mesh>
              <uri>model://aws_robomaker_warehouse_RoofB_01/meshes/aws_robomaker_warehouse_RoofB_01_collision.DAE</uri>
              <scale>1 1 1</scale>
            </mesh>
          </geometry>
          <surface>
            <friction>
              <ode>
                <mu>0.6</mu>
                <mu2>0.6</mu2>
                <fdir1>0 0 0</fdir1>
                <slip1>0</slip1>
                <slip2>0</slip2>
              </ode>
              <torsional>
                <coefficient>1</coefficient>
                <patch_radius>0</patch_radius>
                <surface_radius>0</surface_radius>
                <use_patch_radius>1</use_patch_radius>
                <ode>
                  <slip>0</slip>
                </ode>
              </torsional>
            </friction>
            <contact>
              <ode/>
            </contact>
            <bounce/>
          </surface>
          <max_contacts>10</max_contacts>
        </collision>
        <visual name='visual'>
          <geometry>
            <mesh>
              <uri>model://aws_robomaker_warehouse_RoofB_01/meshes/aws_robomaker_warehouse_RoofB_01_visual.DAE</uri>
            </mesh>
          </geometry>
          <meta>
            <layer>3</layer>
          </meta>
        </visual>
        <pose relative_to='aws_robomaker_warehouse_RoofB_01::__model__'>0 0 0 0 -0 0</pose>
        <self_collide>0</self_collide>
        <enable_wind>0</enable_wind>
        <kinematic>0</kinematic>
      </link>
      <static>1</static>
      <pose>0 0 0 0 -0 0</pose>
    </model>
    <model name='aws_robomaker_warehouse_ShelfF_01_001'>
      <frame name='aws_robomaker_warehouse_ShelfF_01::__model__' attached_to='aws_robomaker_warehouse_ShelfF_01::link'>
        <pose relative_to='__model__'>0 0 0 0 -0 0</pose>
      </frame>
      <link name='aws_robomaker_warehouse_ShelfF_01::link'>
        <inertial>
          <mass>30</mass>
          <inertia>
            <ixx>907.144</ixx>
            <ixy>0</ixy>
            <ixz>0</ixz>
            <iyy>104.95</iyy>
            <iyz>0</iyz>
            <izz>824.248</izz>
          </inertia>
        </inertial>
        <collision name='collision'>
          <geometry>
            <mesh>
              <uri>model://aws_robomaker_warehouse_ShelfF_01/meshes/aws_robomaker_warehouse_ShelfF_01_collision.DAE</uri>
              <scale>1 1 1</scale>
            </mesh>
          </geometry>
          <surface>
            <friction>
              <ode>
                <mu>0.2</mu>
                <mu2>0.2</mu2>
                <fdir1>0 0 0</fdir1>
                <slip1>0</slip1>
                <slip2>0</slip2>
              </ode>
              <torsional>
                <ode/>
              </torsional>
            </friction>
            <contact>
              <ode/>
            </contact>
            <bounce/>
          </surface>
          <max_contacts>10</max_contacts>
        </collision>
        <visual name='visual'>
          <geometry>
            <mesh>
              <uri>model://aws_robomaker_warehouse_ShelfF_01/meshes/aws_robomaker_warehouse_ShelfF_01_visual.DAE</uri>
            </mesh>
          </geometry>
          <meta>
            <layer>1</layer>
          </meta>
        </visual>
        <pose relative_to='aws_robomaker_warehouse_ShelfF_01::__model__'>0 0 0 0 -0 0</pose>
        <self_collide>0</self_collide>
        <enable_wind>0</enable_wind>
        <kinematic>0</kinematic>
      </link>
      <static>1</static>
      <pose>-5.79514 -0.956635 0 0 -0 0</pose>
    </model>
    <model name='aws_robomaker_warehouse_WallB_01_001'>
      <frame name='aws_robomaker_warehouse_WallB_01::__model__' attached_to='aws_robomaker_warehouse_WallB_01::link'>
        <pose relative_to='__model__'>0 0 0 0 -0 0</pose>
      </frame>
      <link name='aws_robomaker_warehouse_WallB_01::link'>
        <inertial>
          <mass>1000</mass>
          <inertia>
            <ixx>840083</ixx>
            <ixy>0</ixy>
            <ixz>0</ixz>
            <iyy>475500</iyy>
            <iyz>0</iyz>
            <izz>1.30208e+06</izz>
          </inertia>
        </inertial>
        <collision name='collision'>
          <geometry>
            <mesh>
              <uri>model://aws_robomaker_warehouse_WallB_01/meshes/aws_robomaker_warehouse_WallB_01_collision.DAE</uri>
              <scale>1 1 1</scale>
            </mesh>
          </geometry>
          <surface>
            <friction>
              <ode>
                <mu>0.5</mu>
                <mu2>0.5</mu2>
                <fdir1>0 0 0</fdir1>
                <slip1>0</slip1>
                <slip2>0</slip2>
              </ode>
              <torsional>
                <ode/>
              </torsional>
            </friction>
            <contact>
              <ode/>
            </contact>
            <bounce/>
          </surface>
          <max_contacts>10</max_contacts>
        </collision>
        <visual name='visual'>
          <geometry>
            <mesh>
              <uri>model://aws_robomaker_warehouse_WallB_01/meshes/aws_robomaker_warehouse_WallB_01_visual.DAE</uri>
            </mesh>
          </geometry>
          <meta>
            <layer>2</layer>
          </meta>
        </visual>
        <pose relative_to='aws_robomaker_warehouse_WallB_01::__model__'>0 0 0 0 -0 0</pose>
        <self_collide>0</self_collide>
        <enable_wind>0</enable_wind>
        <kinematic>0</kinematic>
      </link>
      <static>1</static>
      <pose>0 0 0 0 -0 0</pose>
    </model>
    <model name='aws_robomaker_warehouse_ShelfE_01_003'>
      <frame name='aws_robomaker_warehouse_ShelfE_01::__model__' attached_to='aws_robomaker_warehouse_ShelfE_01::link'>
        <pose relative_to='__model__'>0 0 0 0 -0 0</pose>
      </frame>
      <link name='aws_robomaker_warehouse_ShelfE_01::link'>
        <inertial>
          <mass>30</mass>
          <inertia>
            <ixx>907.144</ixx>
            <ixy>0</ixy>
            <ixz>0</ixz>
            <iyy>104.95</iyy>
            <iyz>0</iyz>
            <izz>824.248</izz>
          </inertia>
        </inertial>
        <collision name='collision'>
          <geometry>
            <mesh>
              <uri>model://aws_robomaker_warehouse_ShelfE_01/meshes/aws_robomaker_warehouse_ShelfE_01_collision.DAE</uri>
              <scale>1 1 1</scale>
            </mesh>
          </geometry>
          <surface>
            <friction>
              <ode>
                <mu>0.2</mu>
                <mu2>0.2</mu2>
                <fdir1>0 0 0</fdir1>
                <slip1>0</slip1>
                <slip2>0</slip2>
              </ode>
              <torsional>
                <ode/>
              </torsional>
            </friction>
            <contact>
              <ode/>
            </contact>
            <bounce/>
          </surface>
          <max_contacts>10</max_contacts>
        </collision>
        <visual name='visual'>
          <geometry>
            <mesh>
              <uri>model://aws_robomaker_warehouse_ShelfE_01/meshes/aws_robomaker_warehouse_ShelfE_01_visual.DAE</uri>
            </mesh>
          </geometry>
          <meta>
            <layer>1</layer>
          </meta>
        </visual>
        <pose relative_to='aws_robomaker_warehouse_ShelfE_01::__model__'>0 0 0 0 -0 0</pose>
        <self_collide>0</self_collide>
        <enable_wind>0</enable_wind>
        <kinematic>0</kinematic>
      </link>
      <static>1</static>
      <pose>4.73156 -8.6651 0 0 -0 0</pose>
    </model>
    <model name='aws_robomaker_warehouse_GroundB_01_001'>
      <frame name='aws_robomaker_warehouse_GroundB_01::__model__' attached_to='aws_robomaker_warehouse_GroundB_01::link'>
        <pose relative_to='__model__'>0 0 0 0 -0 0</pose>
      </frame>
      <link name='aws_robomaker_warehouse_GroundB_01::link'>
        <inertial>
          <mass>1000</mass>
          <inertia>
            <ixx>1.20008e+06</ixx>
            <ixy>0</ixy>
            <ixz>0</ixz>
            <iyy>8.33342e+06</iyy>
            <iyz>0</iyz>
            <izz>2.03333e+06</izz>
          </inertia>
        </inertial>
        <collision name='collision'>
          <geometry>
            <mesh>
              <uri>model://aws_robomaker_warehouse_GroundB_01/meshes/aws_robomaker_warehouse_GroundB_01_collision.DAE</uri>
              <scale>1 1 1</scale>
            </mesh>
          </geometry>
          <surface>
            <friction>
              <ode>
                <mu>100</mu>
                <mu2>50</mu2>
                <fdir1>0 0 0</fdir1>
                <slip1>0</slip1>
                <slip2>0</slip2>
              </ode>
              <torsional>
                <ode/>
              </torsional>
            </friction>
            <contact>
              <ode/>
            </contact>
            <bounce/>
          </surface>
          <max_contacts>10</max_contacts>
        </collision>
        <visual name='visual'>
          <geometry>
            <mesh>
              <uri>model://aws_robomaker_warehouse_GroundB_01/meshes/aws_robomaker_warehouse_GroundB_01_visual.DAE</uri>
            </mesh>
          </geometry>
          <meta>
            <layer>1</layer>
          </meta>
        </visual>
        <pose relative_to='aws_robomaker_warehouse_GroundB_01::__model__'>0 0 0 0 -0 0</pose>
        <self_collide>0</self_collide>
        <enable_wind>0</enable_wind>
        <kinematic>0</kinematic>
      </link>
      <static>1</static>
      <pose>0 0 -0.090092 0 -0 0</pose>
    </model>
    <model name='aws_robomaker_warehouse_Lamp_01_005'>
      <frame name='aws_robomaker_warehouse_Lamp_01::__model__' attached_to='aws_robomaker_warehouse_Lamp_01::link'>
        <pose relative_to='__model__'>0 0 0 0 -0 0</pose>
      </frame>
      <link name='aws_robomaker_warehouse_Lamp_01::link'>
        <inertial>
          <mass>30</mass>
          <inertia>
            <ixx>907.144</ixx>
            <ixy>0</ixy>
            <ixz>0</ixz>
            <iyy>104.95</iyy>
            <iyz>0</iyz>
            <izz>824.248</izz>
          </inertia>
        </inertial>
        <collision name='collision'>
          <geometry>
            <mesh>
              <uri>model://aws_robomaker_warehouse_Lamp_01/meshes/aws_robomaker_warehouse_Lamp_01_collision.DAE</uri>
              <scale>1 1 1</scale>
            </mesh>
          </geometry>
          <surface>
            <friction>
              <ode>
                <mu>0.2</mu>
                <mu2>0.2</mu2>
                <fdir1>0 0 0</fdir1>
                <slip1>0</slip1>
                <slip2>0</slip2>
              </ode>
              <torsional>
                <ode/>
              </torsional>
            </friction>
            <contact>
              <ode/>
            </contact>
            <bounce/>
          </surface>
          <max_contacts>10</max_contacts>
        </collision>
        <visual name='visual'>
          <geometry>
            <mesh>
              <uri>model://aws_robomaker_warehouse_Lamp_01/meshes/aws_robomaker_warehouse_Lamp_01_visual.DAE</uri>
            </mesh>
          </geometry>
          <meta>
            <layer>1</layer>
          </meta>
        </visual>
        <pose relative_to='aws_robomaker_warehouse_Lamp_01::__model__'>0 0 0 0 -0 0</pose>
        <self_collide>0</self_collide>
        <enable_wind>0</enable_wind>
        <kinematic>0</kinematic>
      </link>
      <static>1</static>
      <pose>0 0 -4 0 -0 0</pose>
    </model>
    <model name='aws_robomaker_warehouse_Bucket_01_020'>
      <frame name='aws_robomaker_warehouse_Bucket_01::__model__' attached_to='aws_robomaker_warehouse_Bucket_01::body'>
        <pose relative_to='__model__'>0 0 0 0 -0 0</pose>
      </frame>
      <link name='aws_robomaker_warehouse_Bucket_01::body'>
        <inertial>
          <mass>2</mass>
          <pose>0 0 0 0 -0 0</pose>
          <inertia>
            <ixx>0.57</ixx>
            <ixy>0</ixy>
            <ixz>0</ixz>
            <iyy>0.474</iyy>
            <iyz>0</iyz>
            <izz>0.391</izz>
          </inertia>
        </inertial>
        <pose relative_to='aws_robomaker_warehouse_Bucket_01::__model__'>0 0 0 0 -0 0</pose>
        <self_collide>0</self_collide>
        <kinematic>0</kinematic>
        <gravity>1</gravity>
        <visual name='visual'>
          <geometry>
            <mesh>
              <uri>model://aws_robomaker_warehouse_Bucket_01/meshes/aws_robomaker_warehouse_Bucket_01_visual.DAE</uri>
            </mesh>
          </geometry>
          <meta>
            <layer>1</layer>
          </meta>
        </visual>
        <collision name='collision_0'>
          <laser_retro>0</laser_retro>
          <max_contacts>10</max_contacts>
          <pose>0 0 0 0 -0 0</pose>
          <geometry>
            <mesh>
              <uri>model://aws_robomaker_warehouse_Bucket_01/meshes/aws_robomaker_warehouse_Bucket_01_collision.DAE</uri>
              <scale>1 1 1</scale>
            </mesh>
          </geometry>
          <surface>
            <friction>
              <ode>
                <mu>0.4</mu>
                <mu2>0.4</mu2>
                <fdir1>0 0 0</fdir1>
                <slip1>0</slip1>
                <slip2>0</slip2>
              </ode>
              <torsional>
                <coefficient>1</coefficient>
                <patch_radius>0</patch_radius>
                <surface_radius>0</surface_radius>
                <use_patch_radius>1</use_patch_radius>
                <ode>
                  <slip>0</slip>
                </ode>
              </torsional>
            </friction>
            <contact>
              <ode/>
            </contact>
            <bounce/>
          </surface>
        </collision>
        <enable_wind>0</enable_wind>
      </link>
      <static>1</static>
      <pose>0.433449 9.63171 0 0 0 -1.56316</pose>
    </model>
    <model name='aws_robomaker_warehouse_Bucket_01_022'>
      <frame name='aws_robomaker_warehouse_Bucket_01::__model__' attached_to='aws_robomaker_warehouse_Bucket_01::body'>
        <pose relative_to='__model__'>0 0 0 0 -0 0</pose>
      </frame>
      <link name='aws_robomaker_warehouse_Bucket_01::body'>
        <inertial>
          <mass>2</mass>
          <pose>0 0 0 0 -0 0</pose>
          <inertia>
            <ixx>0.57</ixx>
            <ixy>0</ixy>
            <ixz>0</ixz>
            <iyy>0.474</iyy>
            <iyz>0</iyz>
            <izz>0.391</izz>
          </inertia>
        </inertial>
        <pose relative_to='aws_robomaker_warehouse_Bucket_01::__model__'>0 0 0 0 -0 0</pose>
        <self_collide>0</self_collide>
        <kinematic>0</kinematic>
        <gravity>1</gravity>
        <visual name='visual'>
          <geometry>
            <mesh>
              <uri>model://aws_robomaker_warehouse_Bucket_01/meshes/aws_robomaker_warehouse_Bucket_01_visual.DAE</uri>
            </mesh>
          </geometry>
          <meta>
            <layer>1</layer>
          </meta>
        </visual>
        <collision name='collision_0'>
          <laser_retro>0</laser_retro>
          <max_contacts>10</max_contacts>
          <pose>0 0 0 0 -0 0</pose>
          <geometry>
            <mesh>
              <uri>model://aws_robomaker_warehouse_Bucket_01/meshes/aws_robomaker_warehouse_Bucket_01_collision.DAE</uri>
              <scale>1 1 1</scale>
            </mesh>
          </geometry>
          <surface>
            <friction>
              <ode>
                <mu>0.4</mu>
                <mu2>0.4</mu2>
                <fdir1>0 0 0</fdir1>
                <slip1>0</slip1>
                <slip2>0</slip2>
              </ode>
              <torsional>
                <coefficient>1</coefficient>
                <patch_radius>0</patch_radius>
                <surface_radius>0</surface_radius>
                <use_patch_radius>1</use_patch_radius>
                <ode>
                  <slip>0</slip>
                </ode>
              </torsional>
            </friction>
            <contact>
              <ode/>
            </contact>
            <bounce/>
          </surface>
        </collision>
        <enable_wind>0</enable_wind>
      </link>
      <static>1</static>
      <pose>0.433449 8.59 0 0 0 -1.56316</pose>
    </model>
    <model name='aws_robomaker_warehouse_ClutteringA_01_016'>
      <frame name='aws_robomaker_warehouse_ClutteringA_01::__model__' attached_to='aws_robomaker_warehouse_ClutteringA_01::link'>
        <pose relative_to='__model__'>0 0 0 0 -0 0</pose>
      </frame>
      <link name='aws_robomaker_warehouse_ClutteringA_01::link'>
        <inertial>
          <mass>2</mass>
          <inertia>
            <ixx>0.841</ixx>
            <ixy>0</ixy>
            <ixz>0</ixz>
            <iyy>0.954</iyy>
            <iyz>0</iyz>
            <izz>1.422</izz>
          </inertia>
        </inertial>
        <collision name='collision'>
          <geometry>
            <mesh>
              <uri>model://aws_robomaker_warehouse_ClutteringA_01/meshes/aws_robomaker_warehouse_ClutteringA_01_collision.DAE</uri>
              <scale>1 1 1</scale>
            </mesh>
          </geometry>
          <surface>
            <friction>
              <ode>
                <mu>0.6</mu>
                <mu2>0.6</mu2>
                <fdir1>0 0 0</fdir1>
                <slip1>0</slip1>
                <slip2>0</slip2>
              </ode>
              <torsional>
                <coefficient>1</coefficient>
                <patch_radius>0</patch_radius>
                <surface_radius>0</surface_radius>
                <use_patch_radius>1</use_patch_radius>
                <ode>
                  <slip>0</slip>
                </ode>
              </torsional>
            </friction>
            <contact>
              <ode/>
            </contact>
            <bounce/>
          </surface>
          <max_contacts>10</max_contacts>
        </collision>
        <visual name='visual'>
          <geometry>
            <mesh>
              <uri>model://aws_robomaker_warehouse_ClutteringA_01/meshes/aws_robomaker_warehouse_ClutteringA_01_visual.DAE</uri>
            </mesh>
          </geometry>
          <meta>
            <layer>1</layer>
          </meta>
        </visual>
        <pose relative_to='aws_robomaker_warehouse_ClutteringA_01::__model__'>0 0 0 0 -0 0</pose>
        <self_collide>0</self_collide>
        <enable_wind>0</enable_wind>
        <kinematic>0</kinematic>
      </link>
      <static>1</static>
      <pose>5.70814 8.61684 -0.017477 0 -0 0</pose>
    </model>
    <model name='aws_robomaker_warehouse_ClutteringA_01_017'>
      <frame name='aws_robomaker_warehouse_ClutteringA_01::__model__' attached_to='aws_robomaker_warehouse_ClutteringA_01::link'>
        <pose relative_to='__model__'>0 0 0 0 -0 0</pose>
      </frame>
      <link name='aws_robomaker_warehouse_ClutteringA_01::link'>
        <inertial>
          <mass>2</mass>
          <inertia>
            <ixx>0.841</ixx>
            <ixy>0</ixy>
            <ixz>0</ixz>
            <iyy>0.954</iyy>
            <iyz>0</iyz>
            <izz>1.422</izz>
          </inertia>
        </inertial>
        <collision name='collision'>
          <geometry>
            <mesh>
              <uri>model://aws_robomaker_warehouse_ClutteringA_01/meshes/aws_robomaker_warehouse_ClutteringA_01_collision.DAE</uri>
              <scale>1 1 1</scale>
            </mesh>
          </geometry>
          <surface>
            <friction>
              <ode>
                <mu>0.6</mu>
                <mu2>0.6</mu2>
                <fdir1>0 0 0</fdir1>
                <slip1>0</slip1>
                <slip2>0</slip2>
              </ode>
              <torsional>
                <coefficient>1</coefficient>
                <patch_radius>0</patch_radius>
                <surface_radius>0</surface_radius>
                <use_patch_radius>1</use_patch_radius>
                <ode>
                  <slip>0</slip>
                </ode>
              </torsional>
            </friction>
            <contact>
              <ode/>
            </contact>
            <bounce/>
          </surface>
          <max_contacts>10</max_contacts>
        </collision>
        <visual name='visual'>
          <geometry>
            <mesh>
              <uri>model://aws_robomaker_warehouse_ClutteringA_01/meshes/aws_robomaker_warehouse_ClutteringA_01_visual.DAE</uri>
            </mesh>
          </geometry>
          <meta>
            <layer>1</layer>
          </meta>
        </visual>
        <pose relative_to='aws_robomaker_warehouse_ClutteringA_01::__model__'>0 0 0 0 -0 0</pose>
        <self_collide>0</self_collide>
        <enable_wind>0</enable_wind>
        <kinematic>0</kinematic>
      </link>
      <static>1</static>
      <pose>3.40864 8.61684 -0.017477 0 -0 0</pose>
    </model>
    <model name='aws_robomaker_warehouse_ClutteringA_01_018'>
      <frame name='aws_robomaker_warehouse_ClutteringA_01::__model__' attached_to='aws_robomaker_warehouse_ClutteringA_01::link'>
        <pose relative_to='__model__'>0 0 0 0 -0 0</pose>
      </frame>
      <link name='aws_robomaker_warehouse_ClutteringA_01::link'>
        <inertial>
          <mass>2</mass>
          <inertia>
            <ixx>0.841</ixx>
            <ixy>0</ixy>
            <ixz>0</ixz>
            <iyy>0.954</iyy>
            <iyz>0</iyz>
            <izz>1.422</izz>
          </inertia>
        </inertial>
        <collision name='collision'>
          <geometry>
            <mesh>
              <uri>model://aws_robomaker_warehouse_ClutteringA_01/meshes/aws_robomaker_warehouse_ClutteringA_01_collision.DAE</uri>
              <scale>1 1 1</scale>
            </mesh>
          </geometry>
          <surface>
            <friction>
              <ode>
                <mu>0.6</mu>
                <mu2>0.6</mu2>
                <fdir1>0 0 0</fdir1>
                <slip1>0</slip1>
                <slip2>0</slip2>
              </ode>
              <torsional>
                <coefficient>1</coefficient>
                <patch_radius>0</patch_radius>
                <surface_radius>0</surface_radius>
                <use_patch_radius>1</use_patch_radius>
                <ode>
                  <slip>0</slip>
                </ode>
              </torsional>
            </friction>
            <contact>
              <ode/>
            </contact>
            <bounce/>
          </surface>
          <max_contacts>10</max_contacts>
        </collision>
        <visual name='visual'>
          <geometry>
            <mesh>
              <uri>model://aws_robomaker_warehouse_ClutteringA_01/meshes/aws_robomaker_warehouse_ClutteringA_01_visual.DAE</uri>
            </mesh>
          </geometry>
          <meta>
            <layer>1</layer>
          </meta>
        </visual>
        <pose relative_to='aws_robomaker_warehouse_ClutteringA_01::__model__'>0 0 0 0 -0 0</pose>
        <self_collide>0</self_collide>
        <enable_wind>0</enable_wind>
        <kinematic>0</kinematic>
      </link>
      <static>1</static>
      <pose>-1.49129 5.22243 -0.017477 0 0 -1.58319</pose>
    </model>
    <model name='aws_robomaker_warehouse_ClutteringC_01_027'>
      <frame name='aws_robomaker_warehouse_ClutteringC_01::__model__' attached_to='aws_robomaker_warehouse_ClutteringC_01::link'>
        <pose relative_to='__model__'>0 0 0 0 -0 0</pose>
      </frame>
      <link name='aws_robomaker_warehouse_ClutteringC_01::link'>
        <inertial>
          <mass>1</mass>
          <inertia>
            <ixx>1.558</ixx>
            <ixy>0</ixy>
            <ixz>0</ixz>
            <iyy>1.821</iyy>
            <iyz>0</iyz>
            <izz>1.892</izz>
          </inertia>
        </inertial>
        <collision name='collision'>
          <geometry>
            <mesh>
              <uri>model://aws_robomaker_warehouse_ClutteringC_01/meshes/aws_robomaker_warehouse_ClutteringC_01_collision.DAE</uri>
              <scale>1 1 1</scale>
            </mesh>
          </geometry>
          <surface>
            <friction>
              <ode>
                <mu>0.6</mu>
                <mu2>0.6</mu2>
                <fdir1>0 0 0</fdir1>
                <slip1>0</slip1>
                <slip2>0</slip2>
              </ode>
              <torsional>
                <coefficient>1</coefficient>
                <patch_radius>0</patch_radius>
                <surface_radius>0</surface_radius>
                <use_patch_radius>1</use_patch_radius>
                <ode>
                  <slip>0</slip>
                </ode>
              </torsional>
            </friction>
            <contact>
              <ode/>
            </contact>
            <bounce/>
          </surface>
          <max_contacts>10</max_contacts>
        </collision>
        <visual name='visual'>
          <geometry>
            <mesh>
              <uri>model://aws_robomaker_warehouse_ClutteringC_01/meshes/aws_robomaker_warehouse_ClutteringC_01_visual.DAE</uri>
            </mesh>
          </geometry>
          <meta>
            <layer>1</layer>
          </meta>
        </visual>
        <pose relative_to='aws_robomaker_warehouse_ClutteringC_01::__model__'>0 0 0 0 -0 0</pose>
        <self_collide>0</self_collide>
        <enable_wind>0</enable_wind>
        <kinematic>0</kinematic>
      </link>
      <static>1</static>
      <pose>3.32496 3.82245 -0.012064 0 -0 1.56387</pose>
    </model>
    <model name='aws_robomaker_warehouse_ClutteringC_01_028'>
      <frame name='aws_robomaker_warehouse_ClutteringC_01::__model__' attached_to='aws_robomaker_warehouse_ClutteringC_01::link'>
        <pose relative_to='__model__'>0 0 0 0 -0 0</pose>
      </frame>
      <link name='aws_robomaker_warehouse_ClutteringC_01::link'>
        <inertial>
          <mass>1</mass>
          <inertia>
            <ixx>1.558</ixx>
            <ixy>0</ixy>
            <ixz>0</ixz>
            <iyy>1.821</iyy>
            <iyz>0</iyz>
            <izz>1.892</izz>
          </inertia>
        </inertial>
        <collision name='collision'>
          <geometry>
            <mesh>
              <uri>model://aws_robomaker_warehouse_ClutteringC_01/meshes/aws_robomaker_warehouse_ClutteringC_01_collision.DAE</uri>
              <scale>1 1 1</scale>
            </mesh>
          </geometry>
          <surface>
            <friction>
              <ode>
                <mu>0.6</mu>
                <mu2>0.6</mu2>
                <fdir1>0 0 0</fdir1>
                <slip1>0</slip1>
                <slip2>0</slip2>
              </ode>
              <torsional>
                <coefficient>1</coefficient>
                <patch_radius>0</patch_radius>
                <surface_radius>0</surface_radius>
                <use_patch_radius>1</use_patch_radius>
                <ode>
                  <slip>0</slip>
                </ode>
              </torsional>
            </friction>
            <contact>
              <ode/>
            </contact>
            <bounce/>
          </surface>
          <max_contacts>10</max_contacts>
        </collision>
        <visual name='visual'>
          <geometry>
            <mesh>
              <uri>model://aws_robomaker_warehouse_ClutteringC_01/meshes/aws_robomaker_warehouse_ClutteringC_01_visual.DAE</uri>
            </mesh>
          </geometry>
          <meta>
            <layer>1</layer>
          </meta>
        </visual>
        <pose relative_to='aws_robomaker_warehouse_ClutteringC_01::__model__'>0 0 0 0 -0 0</pose>
        <self_collide>0</self_collide>
        <enable_wind>0</enable_wind>
        <kinematic>0</kinematic>
      </link>
      <static>1</static>
      <pose>5.54171 3.81648 -0.015663 0 0 -1.58319</pose>
    </model>
    <model name='aws_robomaker_warehouse_ClutteringC_01_029'>
      <frame name='aws_robomaker_warehouse_ClutteringC_01::__model__' attached_to='aws_robomaker_warehouse_ClutteringC_01::link'>
        <pose relative_to='__model__'>0 0 0 0 -0 0</pose>
      </frame>
      <link name='aws_robomaker_warehouse_ClutteringC_01::link'>
        <inertial>
          <mass>1</mass>
          <inertia>
            <ixx>1.558</ixx>
            <ixy>0</ixy>
            <ixz>0</ixz>
            <iyy>1.821</iyy>
            <iyz>0</iyz>
            <izz>1.892</izz>
          </inertia>
        </inertial>
        <collision name='collision'>
          <geometry>
            <mesh>
              <uri>model://aws_robomaker_warehouse_ClutteringC_01/meshes/aws_robomaker_warehouse_ClutteringC_01_collision.DAE</uri>
              <scale>1 1 1</scale>
            </mesh>
          </geometry>
          <surface>
            <friction>
              <ode>
                <mu>0.6</mu>
                <mu2>0.6</mu2>
                <fdir1>0 0 0</fdir1>
                <slip1>0</slip1>
                <slip2>0</slip2>
              </ode>
              <torsional>
                <coefficient>1</coefficient>
                <patch_radius>0</patch_radius>
                <surface_radius>0</surface_radius>
                <use_patch_radius>1</use_patch_radius>
                <ode>
                  <slip>0</slip>
                </ode>
              </torsional>
            </friction>
            <contact>
              <ode/>
            </contact>
            <bounce/>
          </surface>
          <max_contacts>10</max_contacts>
        </collision>
        <visual name='visual'>
          <geometry>
            <mesh>
              <uri>model://aws_robomaker_warehouse_ClutteringC_01/meshes/aws_robomaker_warehouse_ClutteringC_01_visual.DAE</uri>
            </mesh>
          </geometry>
          <meta>
            <layer>1</layer>
          </meta>
        </visual>
        <pose relative_to='aws_robomaker_warehouse_ClutteringC_01::__model__'>0 0 0 0 -0 0</pose>
        <self_collide>0</self_collide>
        <enable_wind>0</enable_wind>
        <kinematic>0</kinematic>
      </link>
      <static>1</static>
      <pose>5.38424 6.13715 0 0 -0 -3.13319</pose>
    </model>
    <model name='aws_robomaker_warehouse_ClutteringC_01_030'>
      <frame name='aws_robomaker_warehouse_ClutteringC_01::__model__' attached_to='aws_robomaker_warehouse_ClutteringC_01::link'>
        <pose relative_to='__model__'>0 0 0 0 -0 0</pose>
      </frame>
      <link name='aws_robomaker_warehouse_ClutteringC_01::link'>
        <inertial>
          <mass>1</mass>
          <inertia>
            <ixx>1.558</ixx>
            <ixy>0</ixy>
            <ixz>0</ixz>
            <iyy>1.821</iyy>
            <iyz>0</iyz>
            <izz>1.892</izz>
          </inertia>
        </inertial>
        <collision name='collision'>
          <geometry>
            <mesh>
              <uri>model://aws_robomaker_warehouse_ClutteringC_01/meshes/aws_robomaker_warehouse_ClutteringC_01_collision.DAE</uri>
              <scale>1 1 1</scale>
            </mesh>
          </geometry>
          <surface>
            <friction>
              <ode>
                <mu>0.6</mu>
                <mu2>0.6</mu2>
                <fdir1>0 0 0</fdir1>
                <slip1>0</slip1>
                <slip2>0</slip2>
              </ode>
              <torsional>
                <coefficient>1</coefficient>
                <patch_radius>0</patch_radius>
                <surface_radius>0</surface_radius>
                <use_patch_radius>1</use_patch_radius>
                <ode>
                  <slip>0</slip>
                </ode>
              </torsional>
            </friction>
            <contact>
              <ode/>
            </contact>
            <bounce/>
          </surface>
          <max_contacts>10</max_contacts>
        </collision>
        <visual name='visual'>
          <geometry>
            <mesh>
              <uri>model://aws_robomaker_warehouse_ClutteringC_01/meshes/aws_robomaker_warehouse_ClutteringC_01_visual.DAE</uri>
            </mesh>
          </geometry>
          <meta>
            <layer>1</layer>
          </meta>
        </visual>
        <pose relative_to='aws_robomaker_warehouse_ClutteringC_01::__model__'>0 0 0 0 -0 0</pose>
        <self_collide>0</self_collide>
        <enable_wind>0</enable_wind>
        <kinematic>0</kinematic>
      </link>
      <static>1</static>
      <pose>3.236 6.13715 0 0 -0 -3.13319</pose>
    </model>
    <model name='aws_robomaker_warehouse_ClutteringC_01_032'>
      <frame name='aws_robomaker_warehouse_ClutteringC_01::__model__' attached_to='aws_robomaker_warehouse_ClutteringC_01::link'>
        <pose relative_to='__model__'>0 0 0 0 -0 0</pose>
      </frame>
      <link name='aws_robomaker_warehouse_ClutteringC_01::link'>
        <inertial>
          <mass>1</mass>
          <inertia>
            <ixx>1.558</ixx>
            <ixy>0</ixy>
            <ixz>0</ixz>
            <iyy>1.821</iyy>
            <iyz>0</iyz>
            <izz>1.892</izz>
          </inertia>
        </inertial>
        <collision name='collision'>
          <geometry>
            <mesh>
              <uri>model://aws_robomaker_warehouse_ClutteringC_01/meshes/aws_robomaker_warehouse_ClutteringC_01_collision.DAE</uri>
              <scale>1 1 1</scale>
            </mesh>
          </geometry>
          <surface>
            <friction>
              <ode>
                <mu>0.6</mu>
                <mu2>0.6</mu2>
                <fdir1>0 0 0</fdir1>
                <slip1>0</slip1>
                <slip2>0</slip2>
              </ode>
              <torsional>
                <coefficient>1</coefficient>
                <patch_radius>0</patch_radius>
                <surface_radius>0</surface_radius>
                <use_patch_radius>1</use_patch_radius>
                <ode>
                  <slip>0</slip>
                </ode>
              </torsional>
            </friction>
            <contact>
              <ode/>
            </contact>
            <bounce/>
          </surface>
          <max_contacts>10</max_contacts>
        </collision>
        <visual name='visual'>
          <geometry>
            <mesh>
              <uri>model://aws_robomaker_warehouse_ClutteringC_01/meshes/aws_robomaker_warehouse_ClutteringC_01_visual.DAE</uri>
            </mesh>
          </geometry>
          <meta>
            <layer>1</layer>
          </meta>
        </visual>
        <pose relative_to='aws_robomaker_warehouse_ClutteringC_01::__model__'>0 0 0 0 -0 0</pose>
        <self_collide>0</self_collide>
        <enable_wind>0</enable_wind>
        <kinematic>0</kinematic>
      </link>
      <static>1</static>
      <pose>-1.2196 9.407 -0.015663 0 -0 1.56387</pose>
    </model>
    <model name='aws_robomaker_warehouse_TrashCanC_01_002'>
      <frame name='aws_robomaker_warehouse_TrashCanC_01::__model__' attached_to='aws_robomaker_warehouse_TrashCanC_01::link'>
        <pose relative_to='__model__'>0 0 0 0 -0 0</pose>
      </frame>
      <link name='aws_robomaker_warehouse_TrashCanC_01::link'>
        <inertial>
          <mass>1</mass>
          <inertia>
            <ixx>0.2</ixx>
            <ixy>0</ixy>
            <ixz>0</ixz>
            <iyy>0.308</iyy>
            <iyz>0</iyz>
            <izz>0.24</izz>
          </inertia>
        </inertial>
        <collision name='collision'>
          <geometry>
            <mesh>
              <uri>model://aws_robomaker_warehouse_TrashCanC_01/meshes/aws_robomaker_warehouse_TrashCanC_01_collision.DAE</uri>
              <scale>1 1 1</scale>
            </mesh>
          </geometry>
          <surface>
            <friction>
              <ode>
                <mu>0.4</mu>
                <mu2>0.4</mu2>
                <fdir1>0 0 0</fdir1>
                <slip1>0</slip1>
                <slip2>0</slip2>
              </ode>
              <torsional>
                <ode/>
              </torsional>
            </friction>
            <contact>
              <ode/>
            </contact>
            <bounce/>
          </surface>
          <max_contacts>10</max_contacts>
        </collision>
        <visual name='visual'>
          <geometry>
            <mesh>
              <uri>model://aws_robomaker_warehouse_TrashCanC_01/meshes/aws_robomaker_warehouse_TrashCanC_01_visual.DAE</uri>
            </mesh>
          </geometry>
          <meta>
            <layer>1</layer>
          </meta>
        </visual>
        <pose relative_to='aws_robomaker_warehouse_TrashCanC_01::__model__'>0 0 0 0 -0 0</pose>
        <self_collide>0</self_collide>
        <enable_wind>0</enable_wind>
        <kinematic>0</kinematic>
      </link>
      <static>1</static>
      <pose>-1.59244 7.71542 0 0 -0 0</pose>
    </model>
    <light name='Warehouse_CeilingLight_003' type='point'>
      <pose>0 0 9 0 -0 0</pose>
      <diffuse>0.5 0.5 0.5 1</diffuse>
      <specular>0.2 0.2 0.2 1</specular>
      <attenuation>
        <range>80</range>
        <constant>0.3</constant>
        <linear>0.01</linear>
        <quadratic>0.001</quadratic>
      </attenuation>
      <cast_shadows>1</cast_shadows>
      <direction>0.1 0.1 -1</direction>
      <spot>
        <inner_angle>0</inner_angle>
        <outer_angle>0</outer_angle>
        <falloff>0</falloff>
      </spot>
    </light>
    <gui fullscreen='0'>
      <camera name='user_camera'>
        <pose>-0.226025 -0.841991 6.98641 -2.3e-05 1.5698 -1.60034</pose>
        <view_controller>orbit</view_controller>
        <projection_type>perspective</projection_type>
      </camera>
    </gui>
    <magnetic_field>6e-06 2.3e-05 -4.2e-05</magnetic_field>
    <atmosphere type='adiabatic'/>
    <scene>
      <ambient>0.4 0.4 0.4 1</ambient>
      <background>0.7 0.7 0.7 1</background>
      <shadows>1</shadows>
    </scene>
    <audio>
      <device>default</device>
    </audio>
    <wind/>
    <spherical_coordinates>
      <surface_model>EARTH_WGS84</surface_model>
      <latitude_deg>0</latitude_deg>
      <longitude_deg>0</longitude_deg>
      <elevation>0</elevation>
      <heading_deg>0</heading_deg>
    </spherical_coordinates>
    <model name='ranger_mini'>
      <link name='base_link'>
        <inertial>
          <pose>0 0 0 0 -0 0</pose>
          <mass>50</mass>
          <inertia>
            <ixx>1</ixx>
            <ixy>0</ixy>
            <ixz>0</ixz>
            <iyy>1</iyy>
            <iyz>0</iyz>
            <izz>1</izz>
          </inertia>
        </inertial>
        <collision name='base_link_fixed_joint_lump__camera_link_collision'>
          <pose>0.379348 -0.003143 0.09625 1.5708 -0 1.57</pose>
          <geometry>
            <mesh>
              <scale>1 1 1</scale>
              <uri>file:///root/ros2_ws/install/gazebo_ranger/share/gazebo_ranger/meshes/ranger_mini_v2/camera_link.STL</uri>
            </mesh>
          </geometry>
          <max_contacts>10</max_contacts>
          <surface>
            <contact>
              <ode/>
            </contact>
            <bounce/>
            <friction>
              <torsional>
                <ode/>
              </torsional>
              <ode/>
            </friction>
          </surface>
        </collision>
        <collision name='base_link_fixed_joint_lump__imu_link_collision_1'>
          <pose>0.112281 -0.00293 0.15475 -1.5708 0 -0.0008</pose>
          <geometry>
            <mesh>
              <scale>1 1 1</scale>
              <uri>file:///root/ros2_ws/install/gazebo_ranger/share/gazebo_ranger/meshes/ranger_mini_v2/imu_link.STL</uri>
            </mesh>
          </geometry>
          <max_contacts>10</max_contacts>
          <surface>
            <contact>
              <ode/>
            </contact>
            <bounce/>
            <friction>
              <torsional>
                <ode/>
              </torsional>
              <ode/>
            </friction>
          </surface>
        </collision>
        <collision name='base_link_fixed_joint_lump__lidar_connector_link_collision_2'>
          <pose>0.17925 -0.003108 0.30825 1.5708 -0 1.57</pose>
          <geometry>
            <mesh>
              <scale>1 1 1</scale>
              <uri>file:///root/ros2_ws/install/gazebo_ranger/share/gazebo_ranger/meshes/ranger_mini_v2/lidar_link.STL</uri>
            </mesh>
          </geometry>
          <max_contacts>10</max_contacts>
          <surface>
            <contact>
              <ode/>
            </contact>
            <bounce/>
            <friction>
              <torsional>
                <ode/>
              </torsional>
              <ode/>
            </friction>
          </surface>
        </collision>
        <collision name='base_link_fixed_joint_lump__gps2_link_connect_collision_3'>
          <pose>-0.3 0 0 0 -0 0</pose>
          <geometry>
            <box>
              <size>0 0 0</size>
            </box>
          </geometry>
          <surface>
            <contact>
              <ode/>
            </contact>
            <friction>
              <ode/>
              <torsional>
                <ode/>
              </torsional>
            </friction>
            <bounce/>
          </surface>
          <max_contacts>10</max_contacts>
        </collision>
        <collision name='base_link_fixed_joint_lump__gps_link_connect_collision_4'>
          <pose>0.3 0 0 0 -0 0</pose>
          <geometry>
            <box>
              <size>0 0 0</size>
            </box>
          </geometry>
          <surface>
            <contact>
              <ode/>
            </contact>
            <friction>
              <ode/>
              <torsional>
                <ode/>
              </torsional>
            </friction>
            <bounce/>
          </surface>
          <max_contacts>10</max_contacts>
        </collision>
        <visual name='base_link_visual'>
          <pose>0 0 0 0 -0 0</pose>
          <geometry>
            <box>
              <size>0.5 0.0001 0.2</size>
            </box>
          </geometry>
        </visual>
        <visual name='base_link_fixed_joint_lump__ranger_base_visual_1'>
          <pose>0.2 0 -0.1 0 -0 1.57</pose>
          <geometry>
            <mesh>
              <scale>1 1 1</scale>
              <uri>file:///root/ros2_ws/install/gazebo_ranger/share/gazebo_ranger/meshes/ranger_mini_v2/base_link.STL</uri>
            </mesh>
          </geometry>
        </visual>
        <visual name='base_link_fixed_joint_lump__camera_link_visual_2'>
          <pose>0.379348 -0.003143 0.09625 1.5708 -0 1.57</pose>
          <geometry>
            <mesh>
              <scale>1 1 1</scale>
              <uri>file:///root/ros2_ws/install/gazebo_ranger/share/gazebo_ranger/meshes/ranger_mini_v2/camera_link.STL</uri>
            </mesh>
          </geometry>
        </visual>
        <visual name='base_link_fixed_joint_lump__imu_link_visual_3'>
          <pose>0.112281 -0.00293 0.15475 -1.5708 0 -0.0008</pose>
          <geometry>
            <mesh>
              <scale>1 1 1</scale>
              <uri>file:///root/ros2_ws/install/gazebo_ranger/share/gazebo_ranger/meshes/ranger_mini_v2/imu_link.STL</uri>
            </mesh>
          </geometry>
        </visual>
        <visual name='base_link_fixed_joint_lump__lidar_connector_link_visual_4'>
          <pose>0.17925 -0.003108 0.30825 1.5708 -0 1.57</pose>
          <geometry>
            <mesh>
              <scale>1 1 1</scale>
              <uri>file:///root/ros2_ws/install/gazebo_ranger/share/gazebo_ranger/meshes/ranger_mini_v2/lidar_link.STL</uri>
            </mesh>
          </geometry>
        </visual>
        <visual name='base_link_fixed_joint_lump__gps2_link_connect_visual_5'>
          <pose>-0.3 0 0 0 -0 0</pose>
          <geometry>
            <box>
              <size>0.001 0.001 0.001</size>
            </box>
          </geometry>
        </visual>
        <visual name='base_link_fixed_joint_lump__gps_link_connect_visual_6'>
          <pose>0.3 0 0 0 -0 0</pose>
          <geometry>
            <box>
              <size>0.001 0.001 0.001</size>
            </box>
          </geometry>
        </visual>
        <sensor name='ouster-VLP16' type='ray'>
          <visualize>0</visualize>
          <update_rate>10</update_rate>
          <ray>
            <scan>
              <horizontal>
                <samples>512</samples>
                <resolution>1</resolution>
                <min_angle>-3.14159</min_angle>
                <max_angle>3.14159</max_angle>
              </horizontal>
              <vertical>
                <samples>32</samples>
                <resolution>1</resolution>
                <min_angle>-0.261799</min_angle>
                <max_angle>0.261799</max_angle>
              </vertical>
            </scan>
            <range>
              <min>0.3</min>
              <max>131</max>
              <resolution>0.001</resolution>
            </range>
            <noise>
              <type>gaussian</type>
              <mean>0</mean>
              <stddev>0</stddev>
            </noise>
          </ray>
          <plugin name='velodyne_plugin' filename='libgazebo_ros_velodyne_laser.so'>
            <ros>
              <namespace>/</namespace>
              <remapping>~/out:=/points</remapping>
            </ros>
            <topic_name>/points</topic_name>
            <frame_name>ouster</frame_name>
            <min_range>0.9</min_range>
            <max_range>130.0</max_range>
            <gaussianNoise>0.008</gaussianNoise>
          </plugin>
          <pose>0.179248 -0.00279 -0.09175 0.000796 4e-06 0</pose>
        </sensor>
        <sensor name='gps2' type='gps'>
          <always_on>1</always_on>
          <update_rate>10</update_rate>
          <gps>
            <position_sensing>
              <horizontal>
                <noise type='gaussian'>
                  <mean>0</mean>
                  <stddev>0</stddev>
                </noise>
              </horizontal>
              <vertical>
                <noise type='gaussian'>
                  <mean>0</mean>
                  <stddev>0</stddev>
                </noise>
              </vertical>
            </position_sensing>
          </gps>
          <plugin name='gps2' filename='libgazebo_ros_gps_sensor.so'>
            <ros>
              <remapping>~/out:=gps/fix</remapping>
            </ros>
          </plugin>
          <pose>-0.3 0 0 0 -0 0</pose>
        </sensor>
        <sensor name='gps' type='gps'>
          <always_on>1</always_on>
          <update_rate>10</update_rate>
          <gps>
            <position_sensing>
              <horizontal>
                <noise type='gaussian'>
                  <mean>0</mean>
                  <stddev>0</stddev>
                </noise>
              </horizontal>
              <vertical>
                <noise type='gaussian'>
                  <mean>0</mean>
                  <stddev>0</stddev>
                </noise>
              </vertical>
            </position_sensing>
          </gps>
          <plugin name='gps' filename='libgazebo_ros_gps_sensor.so'>
            <ros>
              <remapping>~/out:=gps/fix2</remapping>
            </ros>
          </plugin>
          <pose>0.3 0 0 0 -0 0</pose>
        </sensor>
        <gravity>1</gravity>
        <sensor name='imu' type='imu'>
          <always_on>1</always_on>
          <update_rate>100</update_rate>
          <visualize>1</visualize>
          <topic>/imu</topic>
          <plugin name='imu_plugin' filename='libgazebo_ros_imu_sensor.so'>
            <ros>
              <namespace>/</namespace>
              <remapping>~/out:=/imu</remapping>
            </ros>
            <topicName>/imu</topicName>
            <body_name>imu</body_name>
            <frame_name>ouster</frame_name>
            <updateRateHZ>100</updateRateHZ>
            <gaussianNoise>0.0</gaussianNoise>
            <xyzOffset>0.0 0.0 0.0</xyzOffset>
            <rpyOffset>0.0 0.0 0.0</rpyOffset>
            <initialOrientationAsReference>1</initialOrientationAsReference>
          </plugin>
          <pose>0 0 0 0 -0 0</pose>
          <imu/>
        </sensor>
        <sensor name='kinect_camera' type='depth'>
          <visualize>1</visualize>
          <update_rate>30</update_rate>
          <camera>
            <horizontal_fov>1.089</horizontal_fov>
            <image>
              <format>R8G8B8</format>
              <width>640</width>
              <height>480</height>
            </image>
            <clip>
              <near>0.2</near>
              <far>10</far>
            </clip>
          </camera>
          <plugin name='kinect_camera_controller' filename='libgazebo_ros_camera.so'>
            <ros>
              <namespace>/kinect_camera</namespace>
            </ros>
            <frame_name>kinect_camera_optical</frame_name>
            <min_depth>0.1</min_depth>
            <max_depth>100.0</max_depth>
          </plugin>
          <pose>0.37911 -0.003186 0.1 0 -0 0</pose>
        </sensor>
        <self_collide>0</self_collide>
        <enable_wind>0</enable_wind>
        <kinematic>0</kinematic>
      </link>
      <joint name='fl_steering_wheel' type='revolute'>
        <pose relative_to='base_link'>0.23 0.206 -0.1 0 -0 0</pose>
        <parent>base_link</parent>
        <child>fl_steering_wheel_link</child>
        <axis>
          <xyz>0 0 1</xyz>
          <limit>
            <lower>-2.1</lower>
            <upper>2.1</upper>
            <effort>5</effort>
            <velocity>6.28</velocity>
          </limit>
          <dynamics>
            <spring_reference>0</spring_reference>
            <spring_stiffness>0</spring_stiffness>
          </dynamics>
        </axis>
      </joint>
      <link name='fl_steering_wheel_link'>
        <pose relative_to='fl_steering_wheel'>0 0 0 0 -0 0</pose>
        <inertial>
          <pose>0 0 0 0 -0 0</pose>
          <mass>1</mass>
          <inertia>
            <ixx>0.01</ixx>
            <ixy>0</ixy>
            <ixz>0</ixz>
            <iyy>0.01</iyy>
            <iyz>0</iyz>
            <izz>0.01</izz>
          </inertia>
        </inertial>
        <collision name='fl_steering_wheel_link_collision'>
          <pose>0 0 0.008 0 -0 0</pose>
          <geometry>
            <cylinder>
              <length>0.001</length>
              <radius>0.001</radius>
            </cylinder>
          </geometry>
          <surface>
            <contact>
              <ode/>
            </contact>
            <friction>
              <ode/>
              <torsional>
                <ode/>
              </torsional>
            </friction>
            <bounce/>
          </surface>
          <max_contacts>10</max_contacts>
        </collision>
        <collision name='fl_steering_wheel_link_collision_1'>
          <pose>0 0 0 0 -0 0</pose>
          <geometry>
            <cylinder>
              <length>0.001</length>
              <radius>0.001</radius>
            </cylinder>
          </geometry>
          <surface>
            <contact>
              <ode/>
            </contact>
            <friction>
              <ode/>
              <torsional>
                <ode/>
              </torsional>
            </friction>
            <bounce/>
          </surface>
          <max_contacts>10</max_contacts>
        </collision>
        <visual name='fl_steering_wheel_link_visual'>
          <pose>-0.23 -0.194 0.1 1.57 0 3.14</pose>
          <geometry>
            <mesh>
              <scale>1 1 1</scale>
              <uri>file:///root/ros2_ws/install/gazebo_ranger/share/gazebo_ranger/meshes/ranger_mini_v2/fl.dae</uri>
            </mesh>
          </geometry>
          <material>
            <script>
              <name>Gazebo/White</name>
              <uri>file://media/materials/scripts/gazebo.material</uri>
            </script>
          </material>
        </visual>
        <self_collide>0</self_collide>
        <enable_wind>0</enable_wind>
        <kinematic>0</kinematic>
      </link>
      <joint name='fl_wheel' type='revolute'>
        <pose relative_to='fl_steering_wheel_link'>0.017 -0.01 -0.12 0 -0 1.57</pose>
        <parent>fl_steering_wheel_link</parent>
        <child>fl_wheel_link</child>
        <axis>
          <xyz>1 0 0</xyz>
          <limit>
            <lower>-1e+16</lower>
            <upper>1e+16</upper>
          </limit>
          <dynamics>
            <spring_reference>0</spring_reference>
            <spring_stiffness>0</spring_stiffness>
          </dynamics>
        </axis>
      </joint>
      <link name='fl_wheel_link'>
        <pose relative_to='fl_wheel'>0 0 0 0 -0 0</pose>
        <inertial>
          <pose>0 0 0 0 -0 0</pose>
          <mass>8</mass>
          <inertia>
            <ixx>0.1171</ixx>
            <ixy>0</ixy>
            <ixz>0</ixz>
            <iyy>0.1361</iyy>
            <iyz>0</iyz>
            <izz>0.1171</izz>
          </inertia>
        </inertial>
        <collision name='fl_wheel_link_collision'>
          <pose>0 0 0 3.14159 1.57079 3.14159</pose>
          <geometry>
            <cylinder>
              <length>0.06</length>
              <radius>0.105</radius>
            </cylinder>
          </geometry>
          <surface>
            <contact>
              <ode/>
            </contact>
            <friction>
              <ode/>
              <torsional>
                <ode/>
              </torsional>
            </friction>
            <bounce/>
          </surface>
          <max_contacts>10</max_contacts>
        </collision>
        <visual name='fl_wheel_link_visual'>
          <pose>0 0 0 1.57 -0 0</pose>
          <geometry>
            <mesh>
              <scale>1.15 1.15 1.15</scale>
              <uri>file:///root/ros2_ws/install/gazebo_ranger/share/gazebo_ranger/meshes/ranger_mini_v2/ffl_wheel_link.STL</uri>
            </mesh>
          </geometry>
          <material>
            <script>
              <name>Gazebo/White</name>
              <uri>file://media/materials/scripts/gazebo.material</uri>
            </script>
          </material>
        </visual>
        <self_collide>0</self_collide>
        <enable_wind>0</enable_wind>
        <kinematic>0</kinematic>
      </link>
      <joint name='fr_steering_wheel' type='revolute'>
        <pose relative_to='base_link'>0.23 -0.206 -0.1 0 -0 0</pose>
        <parent>base_link</parent>
        <child>fr_steering_wheel_link</child>
        <axis>
          <xyz>0 0 1</xyz>
          <limit>
            <lower>-2.1</lower>
            <upper>2.1</upper>
            <effort>5</effort>
            <velocity>6.28</velocity>
          </limit>
          <dynamics>
            <spring_reference>0</spring_reference>
            <spring_stiffness>0</spring_stiffness>
          </dynamics>
        </axis>
      </joint>
      <link name='fr_steering_wheel_link'>
        <pose relative_to='fr_steering_wheel'>0 0 0 0 -0 0</pose>
        <inertial>
          <pose>0 0 0 0 -0 0</pose>
          <mass>1</mass>
          <inertia>
            <ixx>0.01</ixx>
            <ixy>0</ixy>
            <ixz>0</ixz>
            <iyy>0.01</iyy>
            <iyz>0</iyz>
            <izz>0.01</izz>
          </inertia>
        </inertial>
        <collision name='fr_steering_wheel_link_collision'>
          <pose>0 0 0.008 0 -0 0</pose>
          <geometry>
            <cylinder>
              <length>0.001</length>
              <radius>0.001</radius>
            </cylinder>
          </geometry>
          <surface>
            <contact>
              <ode/>
            </contact>
            <friction>
              <ode/>
              <torsional>
                <ode/>
              </torsional>
            </friction>
            <bounce/>
          </surface>
          <max_contacts>10</max_contacts>
        </collision>
        <visual name='fr_steering_wheel_link_visual'>
          <pose>-0.23 0.194 0.1 1.57 0 3.14</pose>
          <geometry>
            <mesh>
              <scale>1 1 1</scale>
              <uri>file:///root/ros2_ws/install/gazebo_ranger/share/gazebo_ranger/meshes/ranger_mini_v2/fr.dae</uri>
            </mesh>
          </geometry>
          <material>
            <script>
              <name>Gazebo/White</name>
              <uri>file://media/materials/scripts/gazebo.material</uri>
            </script>
          </material>
        </visual>
        <self_collide>0</self_collide>
        <enable_wind>0</enable_wind>
        <kinematic>0</kinematic>
      </link>
      <joint name='fr_wheel' type='revolute'>
        <pose relative_to='fr_steering_wheel_link'>0.017 0.01 -0.12 0 0 -1.57</pose>
        <parent>fr_steering_wheel_link</parent>
        <child>fr_wheel_link</child>
        <axis>
          <xyz>-1 0 0</xyz>
          <limit>
            <lower>-1e+16</lower>
            <upper>1e+16</upper>
          </limit>
          <dynamics>
            <spring_reference>0</spring_reference>
            <spring_stiffness>0</spring_stiffness>
          </dynamics>
        </axis>
      </joint>
      <link name='fr_wheel_link'>
        <pose relative_to='fr_wheel'>0 0 0 0 -0 0</pose>
        <inertial>
          <pose>0 0 0 0 -0 0</pose>
          <mass>8</mass>
          <inertia>
            <ixx>0.1171</ixx>
            <ixy>0</ixy>
            <ixz>0</ixz>
            <iyy>0.1361</iyy>
            <iyz>0</iyz>
            <izz>0.1171</izz>
          </inertia>
        </inertial>
        <collision name='fr_wheel_link_collision'>
          <pose>0 0 0 3.14159 1.57079 3.14159</pose>
          <geometry>
            <cylinder>
              <length>0.06</length>
              <radius>0.105</radius>
            </cylinder>
          </geometry>
          <surface>
            <contact>
              <ode/>
            </contact>
            <friction>
              <ode/>
              <torsional>
                <ode/>
              </torsional>
            </friction>
            <bounce/>
          </surface>
          <max_contacts>10</max_contacts>
        </collision>
        <visual name='fr_wheel_link_visual'>
          <pose>0 0 0 1.57 -0 0</pose>
          <geometry>
            <mesh>
              <scale>1.15 1.15 1.15</scale>
              <uri>file:///root/ros2_ws/install/gazebo_ranger/share/gazebo_ranger/meshes/ranger_mini_v2/ffl_wheel_link.STL</uri>
            </mesh>
          </geometry>
          <material>
            <script>
              <name>Gazebo/White</name>
              <uri>file://media/materials/scripts/gazebo.material</uri>
            </script>
          </material>
        </visual>
        <self_collide>0</self_collide>
        <enable_wind>0</enable_wind>
        <kinematic>0</kinematic>
      </link>
      <joint name='rl_steering_wheel' type='revolute'>
        <pose relative_to='base_link'>-0.23 0.206 -0.1 0 -0 0</pose>
        <parent>base_link</parent>
        <child>rl_steering_wheel_link</child>
        <axis>
          <xyz>0 0 1</xyz>
          <limit>
            <lower>-2.1</lower>
            <upper>2.1</upper>
            <effort>5</effort>
            <velocity>6.28</velocity>
          </limit>
          <dynamics>
            <spring_reference>0</spring_reference>
            <spring_stiffness>0</spring_stiffness>
          </dynamics>
        </axis>
      </joint>
      <link name='rl_steering_wheel_link'>
        <pose relative_to='rl_steering_wheel'>0 0 0 0 -0 0</pose>
        <inertial>
          <pose>0 0 0 0 -0 0</pose>
          <mass>1</mass>
          <inertia>
            <ixx>0.01</ixx>
            <ixy>0</ixy>
            <ixz>0</ixz>
            <iyy>0.01</iyy>
            <iyz>0</iyz>
            <izz>0.01</izz>
          </inertia>
        </inertial>
        <collision name='rl_steering_wheel_link_collision'>
          <pose>0 0 0.008 0 -0 0</pose>
          <geometry>
            <cylinder>
              <length>0.001</length>
              <radius>0.001</radius>
            </cylinder>
          </geometry>
          <surface>
            <contact>
              <ode/>
            </contact>
            <friction>
              <ode/>
              <torsional>
                <ode/>
              </torsional>
            </friction>
            <bounce/>
          </surface>
          <max_contacts>10</max_contacts>
        </collision>
        <visual name='rl_steering_wheel_link_visual'>
          <pose>-0.23 -0.194 0.1 1.57 0 3.14</pose>
          <geometry>
            <mesh>
              <scale>1 1 1</scale>
              <uri>file:///root/ros2_ws/install/gazebo_ranger/share/gazebo_ranger/meshes/ranger_mini_v2/fl.dae</uri>
            </mesh>
          </geometry>
          <material>
            <script>
              <name>Gazebo/White</name>
              <uri>file://media/materials/scripts/gazebo.material</uri>
            </script>
          </material>
        </visual>
        <self_collide>0</self_collide>
        <enable_wind>0</enable_wind>
        <kinematic>0</kinematic>
      </link>
      <joint name='rl_wheel' type='revolute'>
        <pose relative_to='rl_steering_wheel_link'>0.017 -0.01 -0.12 0 -0 1.57</pose>
        <parent>rl_steering_wheel_link</parent>
        <child>rl_wheel_link</child>
        <axis>
          <xyz>1 0 0</xyz>
          <limit>
            <lower>-1e+16</lower>
            <upper>1e+16</upper>
          </limit>
          <dynamics>
            <spring_reference>0</spring_reference>
            <spring_stiffness>0</spring_stiffness>
          </dynamics>
        </axis>
      </joint>
      <link name='rl_wheel_link'>
        <pose relative_to='rl_wheel'>0 0 0 0 -0 0</pose>
        <inertial>
          <pose>0 0 0 0 -0 0</pose>
          <mass>8</mass>
          <inertia>
            <ixx>0.1171</ixx>
            <ixy>0</ixy>
            <ixz>0</ixz>
            <iyy>0.1361</iyy>
            <iyz>0</iyz>
            <izz>0.1171</izz>
          </inertia>
        </inertial>
        <collision name='rl_wheel_link_collision'>
          <pose>0 0 0 3.14159 1.57079 3.14159</pose>
          <geometry>
            <cylinder>
              <length>0.06</length>
              <radius>0.105</radius>
            </cylinder>
          </geometry>
          <surface>
            <contact>
              <ode/>
            </contact>
            <friction>
              <ode/>
              <torsional>
                <ode/>
              </torsional>
            </friction>
            <bounce/>
          </surface>
          <max_contacts>10</max_contacts>
        </collision>
        <visual name='rl_wheel_link_visual'>
          <pose>0 0 0 1.57 -0 0</pose>
          <geometry>
            <mesh>
              <scale>1.15 1.15 1.15</scale>
              <uri>file:///root/ros2_ws/install/gazebo_ranger/share/gazebo_ranger/meshes/ranger_mini_v2/ffl_wheel_link.STL</uri>
            </mesh>
          </geometry>
          <material>
            <script>
              <name>Gazebo/White</name>
              <uri>file://media/materials/scripts/gazebo.material</uri>
            </script>
          </material>
        </visual>
        <self_collide>0</self_collide>
        <enable_wind>0</enable_wind>
        <kinematic>0</kinematic>
      </link>
      <joint name='rr_steering_wheel' type='revolute'>
        <pose relative_to='base_link'>-0.23 -0.206 -0.1 0 -0 0</pose>
        <parent>base_link</parent>
        <child>rr_steering_wheel_link</child>
        <axis>
          <xyz>0 0 1</xyz>
          <limit>
            <lower>-2.1</lower>
            <upper>2.1</upper>
            <effort>5</effort>
            <velocity>6.28</velocity>
          </limit>
          <dynamics>
            <spring_reference>0</spring_reference>
            <spring_stiffness>0</spring_stiffness>
          </dynamics>
        </axis>
      </joint>
      <link name='rr_steering_wheel_link'>
        <pose relative_to='rr_steering_wheel'>0 0 0 0 -0 0</pose>
        <inertial>
          <pose>0 0 0 0 -0 0</pose>
          <mass>1</mass>
          <inertia>
            <ixx>0.01</ixx>
            <ixy>0</ixy>
            <ixz>0</ixz>
            <iyy>0.01</iyy>
            <iyz>0</iyz>
            <izz>0.01</izz>
          </inertia>
        </inertial>
        <collision name='rr_steering_wheel_link_collision'>
          <pose>0 0 0 0 -0 0</pose>
          <geometry>
            <cylinder>
              <length>0.001</length>
              <radius>0.001</radius>
            </cylinder>
          </geometry>
          <surface>
            <contact>
              <ode/>
            </contact>
            <friction>
              <ode/>
              <torsional>
                <ode/>
              </torsional>
            </friction>
            <bounce/>
          </surface>
          <max_contacts>10</max_contacts>
        </collision>
        <visual name='rr_steering_wheel_link_visual'>
          <pose>-0.23 0.194 0.1 1.57 0 3.14</pose>
          <geometry>
            <mesh>
              <scale>1 1 1</scale>
              <uri>file:///root/ros2_ws/install/gazebo_ranger/share/gazebo_ranger/meshes/ranger_mini_v2/fr.dae</uri>
            </mesh>
          </geometry>
          <material>
            <script>
              <name>Gazebo/White</name>
              <uri>file://media/materials/scripts/gazebo.material</uri>
            </script>
          </material>
        </visual>
        <self_collide>0</self_collide>
        <enable_wind>0</enable_wind>
        <kinematic>0</kinematic>
      </link>
      <joint name='rr_wheel' type='revolute'>
        <pose relative_to='rr_steering_wheel_link'>0.017 0.01 -0.12 0 0 -1.57</pose>
        <parent>rr_steering_wheel_link</parent>
        <child>rr_wheel_link</child>
        <axis>
          <xyz>-1 0 0</xyz>
          <limit>
            <lower>-1e+16</lower>
            <upper>1e+16</upper>
          </limit>
          <dynamics>
            <spring_reference>0</spring_reference>
            <spring_stiffness>0</spring_stiffness>
          </dynamics>
        </axis>
      </joint>
      <link name='rr_wheel_link'>
        <pose relative_to='rr_wheel'>0 0 0 0 -0 0</pose>
        <inertial>
          <pose>0 0 0 0 -0 0</pose>
          <mass>8</mass>
          <inertia>
            <ixx>0.1171</ixx>
            <ixy>0</ixy>
            <ixz>0</ixz>
            <iyy>0.1361</iyy>
            <iyz>0</iyz>
            <izz>0.1171</izz>
          </inertia>
        </inertial>
        <collision name='rr_wheel_link_collision'>
          <pose>0 0 0 3.14159 1.57079 3.14159</pose>
          <geometry>
            <cylinder>
              <length>0.06</length>
              <radius>0.105</radius>
            </cylinder>
          </geometry>
          <surface>
            <contact>
              <ode/>
            </contact>
            <friction>
              <ode/>
              <torsional>
                <ode/>
              </torsional>
            </friction>
            <bounce/>
          </surface>
          <max_contacts>10</max_contacts>
        </collision>
        <visual name='rr_wheel_link_visual'>
          <pose>0 0 0 1.57 -0 0</pose>
          <geometry>
            <mesh>
              <scale>1.15 1.15 1.15</scale>
              <uri>file:///root/ros2_ws/install/gazebo_ranger/share/gazebo_ranger/meshes/ranger_mini_v2/ffl_wheel_link.STL</uri>
            </mesh>
          </geometry>
          <material>
            <script>
              <name>Gazebo/White</name>
              <uri>file://media/materials/scripts/gazebo.material</uri>
            </script>
          </material>
        </visual>
        <self_collide>0</self_collide>
        <enable_wind>0</enable_wind>
        <kinematic>0</kinematic>
      </link>
      <static>0</static>
      <plugin name='gazebo_ros2_control' filename='libgazebo_ros2_control.so'>
        <parameters>/root/ros2_ws/install/gazebo_ranger/share/gazebo_ranger/config/config.yaml</parameters>
      </plugin>
      <pose>0 0 0.5 0 0 -1.5708</pose>
    </model>
    <state world_name='default'>
      <sim_time>185 930000000</sim_time>
      <real_time>51 29840034</real_time>
      <wall_time>1770474414 110267333</wall_time>
      <iterations>43403</iterations>
      <model name='aws_robomaker_warehouse_Bucket_01_020'>
        <pose>0.433449 9.63171 0 0 0 -1.56316</pose>
        <scale>1 1 1</scale>
        <link name='aws_robomaker_warehouse_Bucket_01::body'>
          <pose>0.433449 9.63171 0 0 0 -1.56316</pose>
          <velocity>0 0 0 0 -0 0</velocity>
          <acceleration>0 0 0 0 -0 0</acceleration>
          <wrench>0 0 0 0 -0 0</wrench>
        </link>
      </model>
      <model name='aws_robomaker_warehouse_Bucket_01_022'>
        <pose>0.433449 8.59 0 0 0 -1.56316</pose>
        <scale>1 1 1</scale>
        <link name='aws_robomaker_warehouse_Bucket_01::body'>
          <pose>0.433449 8.59 0 0 0 -1.56316</pose>
          <velocity>0 0 0 0 -0 0</velocity>
          <acceleration>0 0 0 0 -0 0</acceleration>
          <wrench>0 0 0 0 -0 0</wrench>
        </link>
      </model>
      <model name='aws_robomaker_warehouse_ClutteringA_01_016'>
        <pose>5.70814 8.61684 -0.017477 0 -0 0</pose>
        <scale>1 1 1</scale>
        <link name='aws_robomaker_warehouse_ClutteringA_01::link'>
          <pose>5.70814 8.61684 -0.017477 0 -0 0</pose>
          <velocity>0 0 0 0 -0 0</velocity>
          <acceleration>0 0 0 0 -0 0</acceleration>
          <wrench>0 0 0 0 -0 0</wrench>
        </link>
      </model>
      <model name='aws_robomaker_warehouse_ClutteringA_01_017'>
        <pose>3.40864 8.61684 -0.017477 0 -0 0</pose>
        <scale>1 1 1</scale>
        <link name='aws_robomaker_warehouse_ClutteringA_01::link'>
          <pose>3.40864 8.61684 -0.017477 0 -0 0</pose>
          <velocity>0 0 0 0 -0 0</velocity>
          <acceleration>0 0 0 0 -0 0</acceleration>
          <wrench>0 0 0 0 -0 0</wrench>
        </link>
      </model>
      <model name='aws_robomaker_warehouse_ClutteringA_01_018'>
        <pose>-1.49129 5.22243 -0.017477 0 0 -1.58319</pose>
        <scale>1 1 1</scale>
        <link name='aws_robomaker_warehouse_ClutteringA_01::link'>
          <pose>-1.49129 5.22243 -0.017477 0 0 -1.58319</pose>
          <velocity>0 0 0 0 -0 0</velocity>
          <acceleration>0 0 0 0 -0 0</acceleration>
          <wrench>0 0 0 0 -0 0</wrench>
        </link>
      </model>
      <model name='aws_robomaker_warehouse_ClutteringC_01_027'>
        <pose>3.32496 3.82245 -0.012064 0 -0 1.56387</pose>
        <scale>1 1 1</scale>
        <link name='aws_robomaker_warehouse_ClutteringC_01::link'>
          <pose>3.32496 3.82245 -0.012064 0 -0 1.56387</pose>
          <velocity>0 0 0 0 -0 0</velocity>
          <acceleration>0 0 0 0 -0 0</acceleration>
          <wrench>0 0 0 0 -0 0</wrench>
        </link>
      </model>
      <model name='aws_robomaker_warehouse_ClutteringC_01_028'>
        <pose>5.54171 3.81648 -0.015663 0 0 -1.58319</pose>
        <scale>1 1 1</scale>
        <link name='aws_robomaker_warehouse_ClutteringC_01::link'>
          <pose>5.54171 3.81648 -0.015663 0 0 -1.58319</pose>
          <velocity>0 0 0 0 -0 0</velocity>
          <acceleration>0 0 0 0 -0 0</acceleration>
          <wrench>0 0 0 0 -0 0</wrench>
        </link>
      </model>
      <model name='aws_robomaker_warehouse_ClutteringC_01_029'>
        <pose>5.38424 6.13715 0 0 0 -3.13319</pose>
        <scale>1 1 1</scale>
        <link name='aws_robomaker_warehouse_ClutteringC_01::link'>
          <pose>5.38424 6.13715 0 0 -0 -3.13319</pose>
          <velocity>0 0 0 0 -0 0</velocity>
          <acceleration>0 0 0 0 -0 0</acceleration>
          <wrench>0 0 0 0 -0 0</wrench>
        </link>
      </model>
      <model name='aws_robomaker_warehouse_ClutteringC_01_030'>
        <pose>3.236 6.13715 0 0 0 -3.13319</pose>
        <scale>1 1 1</scale>
        <link name='aws_robomaker_warehouse_ClutteringC_01::link'>
          <pose>3.236 6.13715 0 0 -0 -3.13319</pose>
          <velocity>0 0 0 0 -0 0</velocity>
          <acceleration>0 0 0 0 -0 0</acceleration>
          <wrench>0 0 0 0 -0 0</wrench>
        </link>
      </model>
      <model name='aws_robomaker_warehouse_ClutteringC_01_032'>
        <pose>-1.2196 9.407 -0.015663 0 -0 1.56387</pose>
        <scale>1 1 1</scale>
        <link name='aws_robomaker_warehouse_ClutteringC_01::link'>
          <pose>-1.2196 9.407 -0.015663 0 -0 1.56387</pose>
          <velocity>0 0 0 0 -0 0</velocity>
          <acceleration>0 0 0 0 -0 0</acceleration>
          <wrench>0 0 0 0 -0 0</wrench>
        </link>
      </model>
      <model name='aws_robomaker_warehouse_GroundB_01_001'>
        <pose>0 0 -0.090092 0 -0 0</pose>
        <scale>1 1 1</scale>
        <link name='aws_robomaker_warehouse_GroundB_01::link'>
          <pose>0 0 -0.090092 0 -0 0</pose>
          <velocity>0 0 0 0 -0 0</velocity>
          <acceleration>0 0 0 0 -0 0</acceleration>
          <wrench>0 0 0 0 -0 0</wrench>
        </link>
      </model>
      <model name='aws_robomaker_warehouse_Lamp_01_005'>
        <pose>0 0 -4 0 -0 0</pose>
        <scale>1 1 1</scale>
        <link name='aws_robomaker_warehouse_Lamp_01::link'>
          <pose>0 0 -4 0 -0 0</pose>
          <velocity>0 0 0 0 -0 0</velocity>
          <acceleration>0 0 0 0 -0 0</acceleration>
          <wrench>0 0 0 0 -0 0</wrench>
        </link>
      </model>
      <model name='aws_robomaker_warehouse_RoofB_01_001'>
        <pose>0 0 0 0 -0 0</pose>
        <scale>1 1 1</scale>
        <link name='aws_robomaker_warehouse_RoofB_01::link'>
          <pose>0 0 0 0 -0 0</pose>
          <velocity>0 0 0 0 -0 0</velocity>
          <acceleration>0 0 0 0 -0 0</acceleration>
          <wrench>0 0 0 0 -0 0</wrench>
        </link>
      </model>
      <model name='aws_robomaker_warehouse_ShelfE_01_003'>
        <pose>4.73156 -8.6651 0 0 -0 0</pose>
        <scale>1 1 1</scale>
        <link name='aws_robomaker_warehouse_ShelfE_01::link'>
          <pose>4.73156 -8.6651 0 0 -0 0</pose>
          <velocity>0 0 0 0 -0 0</velocity>
          <acceleration>0 0 0 0 -0 0</acceleration>
          <wrench>0 0 0 0 -0 0</wrench>
        </link>
      </model>
      <model name='aws_robomaker_warehouse_ShelfF_01_001'>
        <pose>-5.79514 -0.956635 0 0 -0 0</pose>
        <scale>1 1 1</scale>
        <link name='aws_robomaker_warehouse_ShelfF_01::link'>
          <pose>-5.79514 -0.956635 0 0 -0 0</pose>
          <velocity>0 0 0 0 -0 0</velocity>
          <acceleration>0 0 0 0 -0 0</acceleration>
          <wrench>0 0 0 0 -0 0</wrench>
        </link>
      </model>
      <model name='aws_robomaker_warehouse_TrashCanC_01_002'>
        <pose>-1.59244 7.71542 0 0 -0 0</pose>
        <scale>1 1 1</scale>
        <link name='aws_robomaker_warehouse_TrashCanC_01::link'>
          <pose>-1.59244 7.71542 0 0 -0 0</pose>
          <velocity>0 0 0 0 -0 0</velocity>
          <acceleration>0 0 0 0 -0 0</acceleration>
          <wrench>0 0 0 0 -0 0</wrench>
        </link>
      </model>
      <model name='aws_robomaker_warehouse_WallB_01_001'>
        <pose>0 0 0 0 -0 0</pose>
        <scale>1 1 1</scale>
        <link name='aws_robomaker_warehouse_WallB_01::link'>
          <pose>0 0 0 0 -0 0</pose>
          <velocity>0 0 0 0 -0 0</velocity>
          <acceleration>0 0 0 0 -0 0</acceleration>
          <wrench>0 0 0 0 -0 0</wrench>
        </link>
      </model>
      <model name='ranger_mini'>
        <pose>0.020014 0.054953 0.359224 -2e-06 -1e-06 -1.62505</pose>
        <scale>1 1 1</scale>
        <link name='base_link'>
          <pose>0.020014 0.054953 0.359224 -2e-06 -1e-06 -1.62505</pose>
          <velocity>-0.001189 0.000186 0.00436 -0.002025 -0.014195 -0.000767</velocity>
          <acceleration>-3.58006 0.507499 7.10019 0.878823 0.806094 3.08329</acceleration>
          <wrench>-179.003 25.3749 355.01 0 -0 0</wrench>
        </link>
        <link name='fl_steering_wheel_link'>
          <pose>0.213238 -0.185879 0.259225 -1.7e-05 -4e-06 -1.62506</pose>
          <velocity>-0.000615 -5.7e-05 0.00917 -0.00348 0.004621 -0.010879</velocity>
          <acceleration>-0.718995 -0.250915 17.5716 -0.576622 0.838921 -0.745737</acceleration>
          <wrench>-0.718995 -0.250915 17.5716 0 -0 0</wrench>
        </link>
        <link name='fl_wheel_link'>
          <pose>0.20233 -0.202311 0.139225 0.059792 1.8e-05 -0.055061</pose>
          <velocity>0.00042 -2.6e-05 0.008833 0.00347 0.003722 -0.01134</velocity>
          <acceleration>3.94462 -0.843411 17.2088 0.952488 1.49772 -0.384297</acceleration>
          <wrench>31.557 -6.74729 137.671 0 -0 0</wrench>
        </link>
        <link name='fr_steering_wheel_link'>
          <pose>-0.198154 -0.163538 0.259225 -8e-06 -1e-06 -1.62503</pose>
          <velocity>-0.000752 0.000181 -0.000391 0.003292 0.004982 0.007257</velocity>
          <acceleration>-0.871488 -0.304087 -0.843965 -0.087446 0.478715 -1.45938</acceleration>
          <wrench>-0.871488 -0.304087 -0.843965 0 -0 0</wrench>
        </link>
        <link name='fr_wheel_link'>
          <pose>-0.18909 -0.181055 0.139225 -0.014924 -4e-06 3.08815</pose>
          <velocity>0.000459 -1e-05 -4e-05 0.001636 0.00429 0.006792</velocity>
          <acceleration>-1.82805 -0.671926 -0.41774 -1.40793 0.288678 2.81109</acceleration>
          <wrench>-14.6244 -5.37541 -3.34192 0 -0 0</wrench>
        </link>
        <link name='rl_steering_wheel_link'>
          <pose>0.238182 0.273444 0.259226 -2.3e-05 -7e-06 -1.62506</pose>
          <velocity>-0.000369 3.5e-05 0.00754 -0.000517 0.006557 -0.010513</velocity>
          <acceleration>-0.798477 -0.14081 13.474 2.38629 -1.09628 -0.379265</acceleration>
          <wrench>-0.798477 -0.14081 13.474 0 -0 0</wrench>
        </link>
        <link name='rl_wheel_link'>
          <pose>0.227274 0.257012 0.139226 -0.052296 2.3e-05 -0.055061</pose>
          <velocity>0.000606 9.1e-05 0.007328 0.002224 0.005493 -0.010877</velocity>
          <acceleration>3.47404 -0.99817 14.1449 0.774618 -0.715123 0.965769</acceleration>
          <wrench>27.7923 -7.98536 113.159 0 -0 0</wrench>
        </link>
        <link name='rr_steering_wheel_link'>
          <pose>-0.173211 0.295786 0.259223 -2e-06 1e-06 -1.62504</pose>
          <velocity>0.000641 4.7e-05 0.001476 -0.003891 -0.020944 0.008358</velocity>
          <acceleration>0.195545 -0.420717 -1.444 -0.98713 1.27157 -0.357849</acceleration>
          <wrench>0.195545 -0.420717 -1.444 0 -0 0</wrench>
        </link>
        <link name='rr_wheel_link'>
          <pose>-0.164147 0.278267 0.139225 0.046008 -0 3.08814</pose>
          <velocity>0.000854 2.4e-05 -0.000128 0.001824 0.007906 0.007891</velocity>
          <acceleration>3.89908 -1.58195 -2.38916 -2.88692 -1.40972 1.18954</acceleration>
          <wrench>31.1927 -12.6556 -19.1133 0 -0 0</wrench>
        </link>
      </model>
      <light name='Warehouse_CeilingLight_003'>
        <pose>0 0 9 0 -0 0</pose>
      </light>
    </state>
  </world>
</sdf>
